<sdf version='1.7'>
  <world name='default'>
    <light name='sun' type='directional'>
      <cast_shadows>1</cast_shadows>
      <pose>0 0 10 0 -0 0</pose>
      <diffuse>0.8 0.8 0.8 1</diffuse>
      <specular>0.2 0.2 0.2 1</specular>
      <attenuation>
        <range>1000</range>
        <constant>0.9</constant>
        <linear>0.01</linear>
        <quadratic>0.001</quadratic>
      </attenuation>
      <direction>-0.5 0.1 -0.9</direction>
      <spot>
        <inner_angle>0</inner_angle>
        <outer_angle>0</outer_angle>
        <falloff>0</falloff>
      </spot>
    </light>
    <gravity>0 0 -9.8</gravity>
    <magnetic_field>6e-06 2.3e-05 -4.2e-05</magnetic_field>
    <atmosphere type='adiabatic'/>
    <physics type='ode'>
      <max_step_size>0.001</max_step_size>
      <real_time_factor>1</real_time_factor>
      <real_time_update_rate>1000</real_time_update_rate>
    </physics>
    <scene>
      <ambient>0.4 0.4 0.4 1</ambient>
      <background>0.7 0.7 0.7 1</background>
      <shadows>1</shadows>
    </scene>
    <audio>
      <device>default</device>
    </audio>
    <wind/>
    <spherical_coordinates>
      <surface_model>EARTH_WGS84</surface_model>
      <latitude_deg>0</latitude_deg>
      <longitude_deg>0</longitude_deg>
      <elevation>0</elevation>
      <heading_deg>0</heading_deg>
    </spherical_coordinates>
    <model name='anna'>
      <link name='base_link'>
        <inertial>
          <pose>-0.015193 0.000586 0.08461 0 -0 0</pose>
          <mass>0.503835</mass>
          <inertia>
            <ixx>0.00226673</ixx>
            <ixy>2.56897e-07</ixy>
            <ixz>-2.41723e-05</ixz>
            <iyy>0.00200675</iyy>
            <iyz>1.1059e-07</iyz>
            <izz>0.00400676</izz>
          </inertia>
        </inertial>
        <collision name='base_link_fixed_joint_lump__chassis_collision'>
          <pose>0 0 0.08 0 -0 0</pose>
          <geometry>
            <box>
              <size>0.22 0.2 0.092</size>
            </box>
          </geometry>
          <surface>
            <contact>
              <ode/>
            </contact>
            <friction>
              <ode/>
              <torsional>
                <ode/>
              </torsional>
            </friction>
            <bounce/>
          </surface>
          <max_contacts>10</max_contacts>
        </collision>
        <collision name='base_link_fixed_joint_lump__camera_mount_collision_1'>
          <pose>0.10003 3.4e-05 0.135 0 -0 0</pose>
          <geometry>
            <mesh>
              <scale>1 1 1</scale>
              <uri>model://line_follow_robot_description/meshes/camera_mount.STL</uri>
            </mesh>
          </geometry>
          <surface>
            <contact>
              <ode/>
            </contact>
            <friction>
              <ode/>
              <torsional>
                <ode/>
              </torsional>
            </friction>
            <bounce/>
          </surface>
          <max_contacts>10</max_contacts>
        </collision>
        <collision name='base_link_fixed_joint_lump__camera_hinge_collision_2'>
          <pose>0.12353 3.4e-05 0.1365 1.5708 -0 0</pose>
          <geometry>
            <mesh>
              <scale>1 1 1</scale>
              <uri>model://line_follow_robot_description/meshes/camera_hinge.STL</uri>
            </mesh>
          </geometry>
          <max_contacts>10</max_contacts>
          <surface>
            <contact>
              <ode/>
            </contact>
            <bounce/>
            <friction>
              <torsional>
                <ode/>
              </torsional>
              <ode/>
            </friction>
          </surface>
        </collision>
        <visual name='base_link_fixed_joint_lump__chassis_visual'>
          <pose>0 0 0.08 0 -0 0</pose>
          <geometry>
            <mesh>
              <scale>1 1 1</scale>
              <uri>model://anna/meshes/chassis.STL</uri>
            </mesh>
          </geometry>
          <material>
            <script>
              <name>Gazebo/White</name>
              <uri>file://media/materials/scripts/gazebo.material</uri>
            </script>
          </material>
        </visual>
        <visual name='base_link_fixed_joint_lump__camera_mount_visual_1'>
          <pose>0.10003 3.4e-05 0.135 0 -0 0</pose>
          <geometry>
            <mesh>
              <scale>1 1 1</scale>
              <uri>model://line_follow_robot_description/meshes/camera_mount.STL</uri>
            </mesh>
          </geometry>
          <material>
            <script>
              <name>Gazebo/Green</name>
              <uri>file://media/materials/scripts/gazebo.material</uri>
            </script>
          </material>
        </visual>
        <visual name='base_link_fixed_joint_lump__camera_hinge_visual_2'>
          <pose>0.12353 3.4e-05 0.1365 1.5708 -0 0</pose>
          <geometry>
            <mesh>
              <scale>1 1 1</scale>
              <uri>model://line_follow_robot_description/meshes/camera_hinge.STL</uri>
            </mesh>
          </geometry>
        </visual>
        <self_collide>0</self_collide>
        <enable_wind>0</enable_wind>
        <kinematic>0</kinematic>
      </link>
      <joint name='camera_revolute_joint' type='revolute'>
        <pose relative_to='base_link'>0.12353 3.4e-05 0.1365 1.5708 -0 0</pose>
        <parent>base_link</parent>
        <child>camera_frame</child>
        <axis>
          <xyz>0 0 1</xyz>
          <limit>
            <lower>-0.523599</lower>
            <upper>2.0944</upper>
            <effort>10</effort>
            <velocity>10</velocity>
          </limit>
          <dynamics>
            <damping>0.1</damping>
            <friction>0.01</friction>
            <spring_reference>0</spring_reference>
            <spring_stiffness>0</spring_stiffness>
          </dynamics>
        </axis>
      </joint>
      <link name='camera_frame'>
        <pose relative_to='camera_revolute_joint'>0 0 0 0 -0 0</pose>
        <inertial>
          <pose>-0.0027 -0.020186 0 0 -0 0</pose>
          <mass>0.004</mass>
          <inertia>
            <ixx>8.41848e-07</ixx>
            <ixy>0</ixy>
            <ixz>0</ixz>
            <iyy>4.65403e-07</iyy>
            <iyz>0</iyz>
            <izz>4.97218e-07</izz>
          </inertia>
        </inertial>
        <collision name='camera_frame_collision'>
          <pose>0 0 0 0 -0 0</pose>
          <geometry>
            <mesh>
              <scale>1 1 1</scale>
              <uri>model://line_follow_robot_description/meshes/camera.STL</uri>
            </mesh>
          </geometry>
          <surface>
            <contact>
              <ode/>
            </contact>
            <friction>
              <ode/>
              <torsional>
                <ode/>
              </torsional>
            </friction>
            <bounce/>
          </surface>
          <max_contacts>10</max_contacts>
        </collision>
        <visual name='camera_frame_visual'>
          <pose>0 0 0 0 -0 0</pose>
          <geometry>
            <mesh>
              <scale>1 1 1</scale>
              <uri>model://line_follow_robot_description/meshes/camera_frame.STL</uri>
            </mesh>
          </geometry>
          <material>
            <script>
              <name>Gazebo/Green</name>
              <uri>file://media/materials/scripts/gazebo.material</uri>
            </script>
          </material>
        </visual>
        <sensor name='main_camera' type='camera'>
          <pose>0.018 -0.0145 0 -1.5708 0 0.20944</pose>
          <update_rate>30</update_rate>
          <visualize>1</visualize>
          <camera name='head'>
            <horizontal_fov>1.089</horizontal_fov>
            <image>
              <width>640</width>
              <height>480</height>
              <format>R8G8B8</format>
            </image>
            <clip>
              <near>0.05</near>
              <far>8</far>
            </clip>
            <noise>
              <type>gaussian</type>
              <mean>0</mean>
              <stddev>0.001</stddev>
            </noise>
          </camera>
          <plugin name='camera_controller' filename='libgazebo_ros_camera.so'>
            <always_on>1</always_on>
            <update_rate>0</update_rate>
            <camera_name>anna/main_camera</camera_name>
            <image_topic_name>image_raw</image_topic_name>
            <camera_info_topic_name>camera_info</camera_info_topic_name>
            <frame_name>camera_link_optical</frame_name>
            <hack_baseline>0.07</hack_baseline>
            <distortion_k1>0.0</distortion_k1>
            <distortion_k2>0.0</distortion_k2>
            <distortion_k3>0.0</distortion_k3>
            <distortion_t1>0.0</distortion_t1>
            <distortion_t2>0.0</distortion_t2>
          </plugin>
        </sensor>
        <self_collide>0</self_collide>
        <enable_wind>0</enable_wind>
        <kinematic>0</kinematic>
      </link>
      <joint name='left_front_wheel_joint' type='revolute'>
        <pose relative_to='base_link'>0.082527 0.13327 0.051043 -1.5708 0 0</pose>
        <parent>base_link</parent>
        <child>left_front_wheel</child>
        <axis>
          <xyz>0 0 1</xyz>
          <limit>
            <lower>-1e+16</lower>
            <upper>1e+16</upper>
          </limit>
          <dynamics>
            <spring_reference>0</spring_reference>
            <spring_stiffness>0</spring_stiffness>
          </dynamics>
        </axis>
      </joint>
      <link name='left_front_wheel'>
        <pose relative_to='left_front_wheel_joint'>0 0 0 0 -0 0</pose>
        <inertial>
          <pose>0 0 0 0 -0 0</pose>
          <mass>0.087</mass>
          <inertia>
            <ixx>9.26303e-05</ixx>
            <ixy>0</ixy>
            <ixz>0</ixz>
            <iyy>9.26304e-05</iyy>
            <iyz>0</iyz>
            <izz>0.00015</izz>
          </inertia>
        </inertial>
        <collision name='left_front_wheel_collision'>
          <pose>0 0 0 0 -0 0</pose>
          <geometry>
            <cylinder>
              <length>0.025</length>
              <radius>0.05</radius>
            </cylinder>
          </geometry>
          <surface>
            <contact>
              <ode>
                <kp>1e+06</kp>
                <kd>1</kd>
              </ode>
            </contact>
            <friction>
              <ode>
                <mu>1</mu>
                <mu2>0.2</mu2>
                <fdir1>1 0 0</fdir1>
              </ode>
              <torsional>
                <ode/>
              </torsional>
            </friction>
            <bounce/>
          </surface>
          <max_contacts>10</max_contacts>
        </collision>
        <visual name='left_front_wheel_visual'>
          <pose>0 0 0 0 -0 0</pose>
          <geometry>
            <mesh>
              <scale>1 1 1</scale>
              <uri>model://anna/meshes/wheel_1.STL</uri>
            </mesh>
          </geometry>
          <material>
            <script>
              <name>Gazebo/FlatBlack</name>
              <uri>file://media/materials/scripts/gazebo.material</uri>
            </script>
          </material>
        </visual>
        <self_collide>0</self_collide>
        <enable_wind>0</enable_wind>
        <kinematic>0</kinematic>
      </link>
      <joint name='left_rear_wheel_joint' type='revolute'>
        <pose relative_to='base_link'>-0.082527 0.13327 0.051043 -1.5708 0 0</pose>
        <parent>base_link</parent>
        <child>left_rear_wheel</child>
        <axis>
          <xyz>0 0 1</xyz>
          <limit>
            <lower>-1e+16</lower>
            <upper>1e+16</upper>
          </limit>
          <dynamics>
            <spring_reference>0</spring_reference>
            <spring_stiffness>0</spring_stiffness>
          </dynamics>
        </axis>
      </joint>
      <link name='left_rear_wheel'>
        <pose relative_to='left_rear_wheel_joint'>0 0 0 0 -0 0</pose>
        <inertial>
          <pose>0 0 0 0 -0 0</pose>
          <mass>0.087</mass>
          <inertia>
            <ixx>9.26303e-05</ixx>
            <ixy>0</ixy>
            <ixz>0</ixz>
            <iyy>9.26304e-05</iyy>
            <iyz>0</iyz>
            <izz>0.00015</izz>
          </inertia>
        </inertial>
        <collision name='left_rear_wheel_collision'>
          <pose>0 0 0 0 -0 0</pose>
          <geometry>
            <cylinder>
              <length>0.025</length>
              <radius>0.05</radius>
            </cylinder>
          </geometry>
          <surface>
            <contact>
              <ode>
                <kp>1e+06</kp>
                <kd>1</kd>
              </ode>
            </contact>
            <friction>
              <ode>
                <mu>1</mu>
                <mu2>0.2</mu2>
                <fdir1>1 0 0</fdir1>
              </ode>
              <torsional>
                <ode/>
              </torsional>
            </friction>
            <bounce/>
          </surface>
          <max_contacts>10</max_contacts>
        </collision>
        <visual name='left_rear_wheel_visual'>
          <pose>0 0 0 0 -0 0</pose>
          <geometry>
            <mesh>
              <scale>1 1 1</scale>
              <uri>model://anna/meshes/wheel_1.STL</uri>
            </mesh>
          </geometry>
          <material>
            <script>
              <name>Gazebo/FlatBlack</name>
              <uri>file://media/materials/scripts/gazebo.material</uri>
            </script>
          </material>
        </visual>
        <self_collide>0</self_collide>
        <enable_wind>0</enable_wind>
        <kinematic>0</kinematic>
      </link>
      <joint name='right_front_wheel_joint' type='revolute'>
        <pose relative_to='base_link'>0.082527 -0.13327 0.051043 1.5708 -0 0</pose>
        <parent>base_link</parent>
        <child>right_front_wheel</child>
        <axis>
          <xyz>0 0 -1</xyz>
          <limit>
            <lower>-1e+16</lower>
            <upper>1e+16</upper>
          </limit>
          <dynamics>
            <spring_reference>0</spring_reference>
            <spring_stiffness>0</spring_stiffness>
          </dynamics>
        </axis>
      </joint>
      <link name='right_front_wheel'>
        <pose relative_to='right_front_wheel_joint'>0 0 0 0 -0 0</pose>
        <inertial>
          <pose>0 0 0 0 -0 0</pose>
          <mass>0.087</mass>
          <inertia>
            <ixx>9.26303e-05</ixx>
            <ixy>0</ixy>
            <ixz>0</ixz>
            <iyy>9.26304e-05</iyy>
            <iyz>0</iyz>
            <izz>0.00015</izz>
          </inertia>
        </inertial>
        <collision name='right_front_wheel_collision'>
          <pose>0 0 0 0 -0 0</pose>
          <geometry>
            <cylinder>
              <length>0.025</length>
              <radius>0.05</radius>
            </cylinder>
          </geometry>
          <surface>
            <contact>
              <ode>
                <kp>1e+06</kp>
                <kd>1</kd>
              </ode>
            </contact>
            <friction>
              <ode>
                <mu>1</mu>
                <mu2>0.2</mu2>
                <fdir1>1 0 0</fdir1>
              </ode>
              <torsional>
                <ode/>
              </torsional>
            </friction>
            <bounce/>
          </surface>
          <max_contacts>10</max_contacts>
        </collision>
        <visual name='right_front_wheel_visual'>
          <pose>0 0 0 0 -0 0</pose>
          <geometry>
            <mesh>
              <scale>1 1 1</scale>
              <uri>model://anna/meshes/wheel_1.STL</uri>
            </mesh>
          </geometry>
          <material>
            <script>
              <name>Gazebo/FlatBlack</name>
              <uri>file://media/materials/scripts/gazebo.material</uri>
            </script>
          </material>
        </visual>
        <self_collide>0</self_collide>
        <enable_wind>0</enable_wind>
        <kinematic>0</kinematic>
      </link>
      <joint name='right_rear_wheel_joint' type='revolute'>
        <pose relative_to='base_link'>-0.082527 -0.13327 0.051043 1.5708 -0 0</pose>
        <parent>base_link</parent>
        <child>right_rear_wheel</child>
        <axis>
          <xyz>0 0 -1</xyz>
          <limit>
            <lower>-1e+16</lower>
            <upper>1e+16</upper>
          </limit>
          <dynamics>
            <spring_reference>0</spring_reference>
            <spring_stiffness>0</spring_stiffness>
          </dynamics>
        </axis>
      </joint>
      <link name='right_rear_wheel'>
        <pose relative_to='right_rear_wheel_joint'>0 0 0 0 -0 0</pose>
        <inertial>
          <pose>0 0 0 0 -0 0</pose>
          <mass>0.087</mass>
          <inertia>
            <ixx>9.26303e-05</ixx>
            <ixy>0</ixy>
            <ixz>0</ixz>
            <iyy>9.26304e-05</iyy>
            <iyz>0</iyz>
            <izz>0.00015</izz>
          </inertia>
        </inertial>
        <collision name='right_rear_wheel_collision'>
          <pose>0 0 0 0 -0 0</pose>
          <geometry>
            <cylinder>
              <length>0.025</length>
              <radius>0.05</radius>
            </cylinder>
          </geometry>
          <surface>
            <contact>
              <ode>
                <kp>1e+06</kp>
                <kd>1</kd>
              </ode>
            </contact>
            <friction>
              <ode>
                <mu>1</mu>
                <mu2>0.2</mu2>
                <fdir1>1 0 0</fdir1>
              </ode>
              <torsional>
                <ode/>
              </torsional>
            </friction>
            <bounce/>
          </surface>
          <max_contacts>10</max_contacts>
        </collision>
        <visual name='right_rear_wheel_visual'>
          <pose>0 0 0 0 -0 0</pose>
          <geometry>
            <mesh>
              <scale>1 1 1</scale>
              <uri>model://anna/meshes/wheel_1.STL</uri>
            </mesh>
          </geometry>
          <material>
            <script>
              <name>Gazebo/FlatBlack</name>
              <uri>file://media/materials/scripts/gazebo.material</uri>
            </script>
          </material>
        </visual>
        <self_collide>0</self_collide>
        <enable_wind>0</enable_wind>
        <kinematic>0</kinematic>
      </link>
      <static>0</static>
      <plugin name='gazebo_ros2_control' filename='libgazebo_ros2_control.so'>
        <parameters>/home/lvquang/Desktop/ros2_ws/install/anna/share/anna/config/diff_drive_controller.yaml</parameters>
        <parameters>/home/lvquang/Desktop/ros2_ws/install/anna/share/anna/config/camera_controller.yaml</parameters>
      </plugin>
      <pose>0 0 0 0 -0 0</pose>
    </model>
    <model name='track'>
      <static>1</static>
      <link name='link'>
        <collision name='collision'>
          <geometry>
            <plane>
              <normal>0 0 1</normal>
              <size>5 5</size>
            </plane>
          </geometry>
          <surface>
            <friction>
              <ode>
                <mu>100</mu>
                <mu2>100</mu2>
              </ode>
              <torsional>
                <ode/>
              </torsional>
            </friction>
            <contact>
              <ode/>
            </contact>
            <bounce/>
          </surface>
          <max_contacts>10</max_contacts>
        </collision>
        <visual name='visual'>
          <cast_shadows>0</cast_shadows>
          <pose>0 0 0 0 -0 0</pose>
          <geometry>
            <plane>
              <normal>0 0 1</normal>
              <size>5 5</size>
            </plane>
          </geometry>
          <material>
            <script>
              <uri>file://media/materials/scripts/gazebo.material</uri>
              <name>Gazebo/Track</name>
            </script>
          </material>
        </visual>
        <self_collide>0</self_collide>
        <enable_wind>0</enable_wind>
        <kinematic>0</kinematic>
      </link>
      <pose>-0.998899 0.688269 0 0 -0 0</pose>
    </model>
    <state world_name='default'>
      <sim_time>56 175000000</sim_time>
      <real_time>57 444079999</real_time>
      <wall_time>1694328602 570841441</wall_time>
      <iterations>56175</iterations>
      <model name='anna'>
        <pose>1.3e-05 1.9e-05 -0.001044 0 -1e-06 1.4867</pose>
        <scale>1 1 1</scale>
        <link name='base_link'>
          <pose>1.3e-05 1.9e-05 -0.001044 0 -1e-06 1.4867</pose>
          <velocity>-0 -0 9e-06 -1.1e-05 1e-06 0</velocity>
          <acceleration>0 0 0 -1e-06 0 0</acceleration>
          <wrench>0 0 0 0 -0 0</wrench>
        </link>
        <link name='camera_frame'>
          <pose>0.010355 0.123115 0.135456 1.5708 0.299999 1.4867</pose>
          <velocity>0 1e-06 8e-06 -1.1e-05 1e-06 0</velocity>
          <acceleration>0 0 -0 0.014754 -0.000382 0.000183</acceleration>
          <wrench>0 0 -0 0 -0 0</wrench>
        </link>
        <link name='left_front_wheel'>
          <pose>-0.125854 0.093449 0.049999 -1.5708 0.000669 1.4867</pose>
          <velocity>0 1e-06 9e-06 -1e-05 1e-06 0</velocity>
          <acceleration>5e-06 -0 -1e-06 0.000109 -0.000136 -4e-05</acceleration>
          <wrench>0 -0 -0 0 -0 0</wrench>
        </link>
        <link name='left_rear_wheel'>
          <pose>-0.139718 -0.071022 0.049999 -1.5708 0.000669 1.4867</pose>
          <velocity>0 1e-06 1e-05 -1e-05 1e-06 0</velocity>
          <acceleration>2e-06 -1e-06 1e-06 0.000144 1.4e-05 -3.5e-05</acceleration>
          <wrench>0 -0 0 0 -0 0</wrench>
        </link>
        <link name='right_front_wheel'>
          <pose>0.139744 0.07106 0.049999 1.5708 0.000672 1.4867</pose>
          <velocity>0 1e-06 9e-06 -1.1e-05 1e-06 0</velocity>
          <acceleration>2e-06 1e-06 -1e-06 -0.000147 -0.000178 -3.8e-05</acceleration>
          <wrench>0 0 -0 0 -0 0</wrench>
        </link>
        <link name='right_rear_wheel'>
          <pose>0.12588 -0.093411 0.049999 1.5708 0.000672 1.4867</pose>
          <velocity>0 1e-06 1e-05 -1.1e-05 1e-06 0</velocity>
          <acceleration>-1e-06 0 -5e-06 -0.00011 -1.4e-05 -3.8e-05</acceleration>
          <wrench>-0 0 -0 0 -0 0</wrench>
        </link>
      </model>
      <model name='track'>
        <pose>-0.998899 0.688269 0 0 -0 0</pose>
        <scale>1 1 1</scale>
        <link name='link'>
          <pose>-0.998899 0.688269 0 0 -0 0</pose>
          <velocity>0 0 0 0 -0 0</velocity>
          <acceleration>0 0 0 0 -0 0</acceleration>
          <wrench>0 0 0 0 -0 0</wrench>
        </link>
      </model>
      <light name='sun'>
        <pose>0 0 10 0 -0 0</pose>
      </light>
    </state>
    <gui fullscreen='0'>
      <camera name='user_camera'>
        <pose>0.774872 -1.28178 3.69765 0 1.01964 2.1682</pose>
        <view_controller>orbit</view_controller>
        <projection_type>perspective</projection_type>
      </camera>
    </gui>
  </world>
</sdf>
